[32m2025-04-15 21:56:05 +0000[0m - dagster - [34mDEBUG[0m - internal_preprocessing_job - 94c4adca-2d98-4d19-9a90-da84df4fade2 - 23428 - LOGS_CAPTURED - Started capturing logs in process (pid: 23428).
[32m2025-04-15 21:56:05 +0000[0m - dagster - [34mDEBUG[0m - internal_preprocessing_job - 94c4adca-2d98-4d19-9a90-da84df4fade2 - 23428 - internal_output_sales_table - STEP_START - Started execution of step "internal_output_sales_table".
[32m2025-04-15 21:56:05 +0000[0m - dagster - [34mDEBUG[0m - internal_preprocessing_job - 94c4adca-2d98-4d19-9a90-da84df4fade2 - internal_output_sales_table - Loading file from: storage/internal_sales_by_category using PickledObjectFilesystemIOManager...
[32m2025-04-15 21:56:05 +0000[0m - dagster - [34mDEBUG[0m - internal_preprocessing_job - 94c4adca-2d98-4d19-9a90-da84df4fade2 - 23428 - internal_output_sales_table - LOADED_INPUT - Loaded input "internal_sales_by_category" using input manager "io_manager"
[32m2025-04-15 21:56:05 +0000[0m - dagster - [34mDEBUG[0m - internal_preprocessing_job - 94c4adca-2d98-4d19-9a90-da84df4fade2 - 23428 - internal_output_sales_table - STEP_INPUT - Got input "internal_sales_by_category" of type "Dict[String,DataFrame]". (Type check passed).
[32m2025-04-15 21:56:05 +0000[0m - dagster - [34mINFO[0m - internal_preprocessing_job - 94c4adca-2d98-4d19-9a90-da84df4fade2 - internal_output_sales_table - Saving preprocessed sales data
[32m2025-04-15 21:56:05 +0000[0m - dagster - [34mERROR[0m - [31minternal_preprocessing_job - 94c4adca-2d98-4d19-9a90-da84df4fade2 - 23428 - internal_output_sales_table - STEP_FAILURE - Execution of step "internal_output_sales_table" failed.

dagster._core.errors.DagsterExecutionStepExecutionError: Error occurred while executing op "internal_output_sales_table"::

AttributeError: 'dict' object has no attribute 'select'

Stack Trace:
  File "/workspaces/testing-dagster/.venv/lib/python3.10/site-packages/dagster/_core/execution/plan/utils.py", line 56, in op_execution_error_boundary
    yield
  File "/workspaces/testing-dagster/.venv/lib/python3.10/site-packages/dagster/_utils/__init__.py", line 391, in iterate_with_context
    next_output = next(iterator)
  File "/workspaces/testing-dagster/.venv/lib/python3.10/site-packages/dagster/_core/execution/plan/compute_generator.py", line 127, in _coerce_op_compute_fn_to_iterator
    result = invoke_compute_fn(
  File "/workspaces/testing-dagster/.venv/lib/python3.10/site-packages/dagster/_core/execution/plan/compute_generator.py", line 115, in invoke_compute_fn
    return fn(context, **args_to_pass) if context_arg_provided else fn(**args_to_pass)
  File "/workspaces/testing-dagster/src/clustering/dagster/assets/preprocessing/internal.py", line 242, in internal_output_sales_table
    "num_stores": internal_sales_by_category.select("STORE_NBR").unique().len(),
[0m
