[32m2025-04-15 03:36:06 +0000[0m - dagster - [34mDEBUG[0m - internal_preprocessing_job - f6f5293c-80b2-4a91-b8b9-9743661d31fa - 50189 - LOGS_CAPTURED - Started capturing logs in process (pid: 50189).
[32m2025-04-15 03:36:06 +0000[0m - dagster - [34mDEBUG[0m - internal_preprocessing_job - f6f5293c-80b2-4a91-b8b9-9743661d31fa - 50189 - internal_raw_sales_data - STEP_START - Started execution of step "internal_raw_sales_data".
[32m2025-04-15 03:36:06 +0000[0m - dagster - [34mINFO[0m - internal_preprocessing_job - f6f5293c-80b2-4a91-b8b9-9743661d31fa - internal_raw_sales_data - Reading need state sales data
[32m2025-04-15 03:36:06 +0000[0m - dagster - [34mERROR[0m - [31minternal_preprocessing_job - f6f5293c-80b2-4a91-b8b9-9743661d31fa - 50189 - internal_raw_sales_data - STEP_FAILURE - Execution of step "internal_raw_sales_data" failed.

dagster._core.errors.DagsterExecutionStepExecutionError: Error occurred while executing op "internal_raw_sales_data"::

FileNotFoundError: File not found: ${paths.internal_data_dir}/ns_sales.csv

Stack Trace:
  File "/workspaces/testing-dagster/.venv/lib/python3.10/site-packages/dagster/_core/execution/plan/utils.py", line 56, in op_execution_error_boundary
    yield
  File "/workspaces/testing-dagster/.venv/lib/python3.10/site-packages/dagster/_utils/__init__.py", line 391, in iterate_with_context
    next_output = next(iterator)
  File "/workspaces/testing-dagster/.venv/lib/python3.10/site-packages/dagster/_core/execution/plan/compute_generator.py", line 127, in _coerce_op_compute_fn_to_iterator
    result = invoke_compute_fn(
  File "/workspaces/testing-dagster/.venv/lib/python3.10/site-packages/dagster/_core/execution/plan/compute_generator.py", line 115, in invoke_compute_fn
    return fn(context, **args_to_pass) if context_arg_provided else fn(**args_to_pass)
  File "/workspaces/testing-dagster/src/clustering/dagster/assets/preprocessing/internal.py", line 34, in internal_raw_sales_data
    return context.resources.internal_ns_sales.read()
  File "/workspaces/testing-dagster/src/clustering/io/readers/base.py", line 25, in read
    self._validate_source()
  File "/workspaces/testing-dagster/src/clustering/io/readers/base.py", line 93, in _validate_source
    raise FileNotFoundError(f"File not found: {self.path}")
[0m
