[32m2025-04-15 03:31:36 +0000[0m - dagster - [34mDEBUG[0m - __ASSET_JOB - ee975c62-fde7-41e6-b784-2a24348c0b30 - 33389 - LOGS_CAPTURED - Started capturing logs in process (pid: 33389).
[32m2025-04-15 03:31:36 +0000[0m - dagster - [34mDEBUG[0m - __ASSET_JOB - ee975c62-fde7-41e6-b784-2a24348c0b30 - 33389 - internal_product_category_mapping - STEP_START - Started execution of step "internal_product_category_mapping".
[32m2025-04-15 03:31:36 +0000[0m - dagster - [34mERROR[0m - [31m__ASSET_JOB - ee975c62-fde7-41e6-b784-2a24348c0b30 - 33389 - internal_product_category_mapping - STEP_FAILURE - Execution of step "internal_product_category_mapping" failed.

dagster._core.errors.DagsterExecutionStepExecutionError: Error occurred while executing op "internal_product_category_mapping"::

FileNotFoundError: File not found: ${paths.internal_data_dir}/ns_map.csv

Stack Trace:
  File "/workspaces/testing-dagster/.venv/lib/python3.10/site-packages/dagster/_core/execution/plan/utils.py", line 56, in op_execution_error_boundary
    yield
  File "/workspaces/testing-dagster/.venv/lib/python3.10/site-packages/dagster/_utils/__init__.py", line 391, in iterate_with_context
    next_output = next(iterator)
  File "/workspaces/testing-dagster/.venv/lib/python3.10/site-packages/dagster/_core/execution/plan/compute_generator.py", line 127, in _coerce_op_compute_fn_to_iterator
    result = invoke_compute_fn(
  File "/workspaces/testing-dagster/.venv/lib/python3.10/site-packages/dagster/_core/execution/plan/compute_generator.py", line 115, in invoke_compute_fn
    return fn(context, **args_to_pass) if context_arg_provided else fn(**args_to_pass)
  File "/workspaces/testing-dagster/src/clustering/dagster/assets/preprocessing/internal.py", line 56, in internal_product_category_mapping
    context.resources.internal_ns_map.read()
  File "/workspaces/testing-dagster/src/clustering/io/readers/base.py", line 25, in read
    self._validate_source()
  File "/workspaces/testing-dagster/src/clustering/io/readers/base.py", line 93, in _validate_source
    raise FileNotFoundError(f"File not found: {self.path}")
[0m
